<?xml version="1.0" encoding="UTF-8"?>
<testng-results skipped="0" failed="1" ignored="0" total="1" passed="0">
  <reporter-output>
  </reporter-output>
  <suite name="Default suite" duration-ms="10409" started-at="2022-04-11T19:49:23 IST" finished-at="2022-04-11T19:49:33 IST">
    <groups>
    </groups>
    <test name="Default test" duration-ms="10409" started-at="2022-04-11T19:49:23 IST" finished-at="2022-04-11T19:49:33 IST">
      <class name="com.testNG_Project.Expected_Exception">
        <test-method status="FAIL" signature="TimeOut()[pri:0, instance:com.testNG_Project.Expected_Exception@5bfbf16f]" name="TimeOut" duration-ms="10214" started-at="2022-04-11T19:49:23 IST" finished-at="2022-04-11T19:49:33 IST">
          <exception class="org.testng.TestException">
            <message>
              <![CDATA[
Expected exception of any of types [class com.testNG_Project.Expected_Exception, class org.openqa.selenium.TimeoutException] but got org.testng.internal.thread.ThreadTimeoutException: Method com.testNG_Project.Expected_Exception.TimeOut() didn't finish within the time-out 10000]]>
            </message>
            <full-stacktrace>
              <![CDATA[org.testng.TestException: 
Expected exception of any of types [class com.testNG_Project.Expected_Exception, class org.openqa.selenium.TimeoutException] but got org.testng.internal.thread.ThreadTimeoutException: Method com.testNG_Project.Expected_Exception.TimeOut() didn't finish within the time-out 10000
at org.testng.internal.ExpectedExceptionsHolder.wrongException(ExpectedExceptionsHolder.java:68)
at org.testng.internal.TestInvoker.considerExceptions(TestInvoker.java:739)
at org.testng.internal.TestInvoker.invokeMethod(TestInvoker.java:634)
at org.testng.internal.TestInvoker.invokeTestMethod(TestInvoker.java:173)
at org.testng.internal.MethodRunner.runInSequence(MethodRunner.java:46)
at org.testng.internal.TestInvoker$MethodInvocationAgent.invoke(TestInvoker.java:824)
at org.testng.internal.TestInvoker.invokeTestMethods(TestInvoker.java:146)
at org.testng.internal.TestMethodWorker.invokeTestMethods(TestMethodWorker.java:146)
at org.testng.internal.TestMethodWorker.run(TestMethodWorker.java:128)
at java.util.ArrayList.forEach(Unknown Source)
at org.testng.TestRunner.privateRun(TestRunner.java:794)
at org.testng.TestRunner.run(TestRunner.java:596)
at org.testng.SuiteRunner.runTest(SuiteRunner.java:377)
at org.testng.SuiteRunner.runSequentially(SuiteRunner.java:371)
at org.testng.SuiteRunner.privateRun(SuiteRunner.java:332)
at org.testng.SuiteRunner.run(SuiteRunner.java:276)
at org.testng.SuiteRunnerWorker.runSuite(SuiteRunnerWorker.java:53)
at org.testng.SuiteRunnerWorker.run(SuiteRunnerWorker.java:96)
at org.testng.TestNG.runSuitesSequentially(TestNG.java:1212)
at org.testng.TestNG.runSuitesLocally(TestNG.java:1134)
at org.testng.TestNG.runSuites(TestNG.java:1063)
at org.testng.TestNG.run(TestNG.java:1031)
at org.testng.remote.AbstractRemoteTestNG.run(AbstractRemoteTestNG.java:115)
at org.testng.remote.RemoteTestNG.initAndRun(RemoteTestNG.java:251)
at org.testng.remote.RemoteTestNG.main(RemoteTestNG.java:77)
Caused by: org.testng.internal.thread.ThreadTimeoutException: Method com.testNG_Project.Expected_Exception.TimeOut() didn't finish within the time-out 10000
at org.testng.internal.MethodInvocationHelper.invokeWithTimeoutWithNewExecutor(MethodInvocationHelper.java:384)
at org.testng.internal.MethodInvocationHelper.invokeWithTimeout(MethodInvocationHelper.java:283)
at org.testng.internal.TestInvoker.invokeMethod(TestInvoker.java:604)
... 22 more
]]>
            </full-stacktrace>
          </exception> <!-- org.testng.TestException -->
          <reporter-output>
          </reporter-output>
        </test-method> <!-- TimeOut -->
      </class> <!-- com.testNG_Project.Expected_Exception -->
    </test> <!-- Default test -->
  </suite> <!-- Default suite -->
</testng-results>
